<?xml version="1.0"?>
<sdf version="1.7">
    <!--include defination-->
    <xmacro_include uri="model://rm21_armor_module/rm21_armor_module.def.xmacro" />
    <xmacro_include uri="model://rm21_light_indicator_module/rm21_light_indicator_module.def.xmacro" />
    <xmacro_include uri="model://rm21_speed_monitor_module/rm21_speed_monitor_module.def.xmacro" />
    <xmacro_include uri="model://rmua19_standard_robot/chassis_wheel.def.xmacro" />
    <!--macro defination: rmua19_standard_robot-->
    <xmacro_define_block name="rmua19_standard_robot" params="sticker_type">
        <!--chassis-->
        <link name="chassis" >
            <inertial>
                <pose>0 0 0.055 0 0 0</pose>
                <xmacro_block name="inertia_box"  m="15.0" x="0.36" y="0.24" z="0.13"/>
            </inertial>
            <visual name="chassis_visual">
                <xmacro_block name="geometry_mesh" uri="model://rmua19_standard_robot/meshes/chassis_base.dae"/>
            </visual>
            <collision name="chassis_base_collision">
                <pose>0 0 0.045 0 0 0</pose>
                <xmacro_block name="geometry_box" x="0.36" y="0.24" z="0.13"/>
            </collision>
            <collision name="chassis_projectile_container_collision">
                <pose>-0.122 0 0.177 0 0 0</pose>
                <xmacro_block name="geometry_box" x="0.1" y="0.18" z="0.146"/>
            </collision>
            <collision name="chassis_fornt_wheel_holder_collision">
                <pose>0.208 0 0 0 0 0</pose>
                <xmacro_block name="geometry_box" x="0.055" y="0.367" z="0.055"/>
            </collision>
            <collision name="chassis_rear_wheel_holder_collision">
                <pose>-0.208 0 0 0 0 0</pose>
                <xmacro_block name="geometry_box" x="0.055" y="0.367" z="0.055"/>
            </collision>
            <sensor name="chassis_imu" type="imu" >
                <always_on>1</always_on>
                <update_rate>200</update_rate>
            </sensor>
        </link>
        <!--front_left wheel link and joint-->
        <xmacro_block name="chassis_wheel_l"  prefix="front_left" parent="chassis" pose="0.207 0.194 0 0 0 0"/>
        <!--front_right wheel link and joint-->
        <xmacro_block name="chassis_wheel_r"  prefix="front_right" parent="chassis" pose="0.207 -0.194 0 0 0 0"/>
        <!--rear_left wheel link and joint-->
        <xmacro_block name="chassis_wheel_r"  prefix="rear_left" parent="chassis" pose="-0.207 0.194 0 0 0 0"/>
        <!--rear_right wheel link and joint-->
        <xmacro_block name="chassis_wheel_l"  prefix="rear_right" parent="chassis" pose="-0.207 -0.194 0 0 0 0"/>
        <!--gimbal yaw module-->
        <joint name="gimbal_yaw_joint" type="revolute">
            <pose relative_to='chassis'>0 0 0.1376 0 0 0</pose>
            <parent>chassis</parent>
            <child>gimbal_yaw</child>
            <axis>
                <xyz>0 0 1</xyz>
                <limit>
                    <lower>-1.57</lower>
                    <upper>1.57</upper>
                </limit>
            </axis>
        </joint>
        <link name="gimbal_yaw" >
            <pose relative_to="gimbal_yaw_joint">0 0 0 0 0 0</pose>
            <inertial>
                <pose>0 0 0.06 0 0 0</pose>
                <xmacro_block name="inertia_cylinder"  m="1.0" r="0.05" l="0.17"/>
            </inertial>
            <visual name="visual">
                <xmacro_block name="geometry_mesh" uri="model://rmua19_standard_robot/meshes/gimbal_yaw.dae"/>
            </visual>
            <collision name="collision">
                <pose>0 0 0.0885 0 0 0</pose>
                <xmacro_block name="geometry_box" x="0.065" y="0.117" z="0.177"/>
            </collision>
        </link>
        <!--gimbal pitch module-->
        <joint name="gimbal_pitch_joint" type="revolute">
            <pose relative_to='gimbal_yaw'>0 0.004 0.16 0 0 0</pose>
            <parent>gimbal_yaw</parent>
            <child>gimbal_pitch</child>
            <axis>
                <xyz>0 1 0</xyz>
                <limit>
                    <lower>${-3.14*0.25}</lower>
                    <upper>${3.14*0.18}</upper>
                </limit>
            </axis>
        </joint>
        <link name="gimbal_pitch" >
            <pose relative_to="gimbal_pitch_joint">0 0 0 0 0 0</pose>
            <inertial>
                <pose>0.02 0 0 0 0 0</pose>
                <xmacro_block name="inertia_box"  m="0.5" x="0.25" y="0.09" z="0.10" />
            </inertial>
            <visual name="visual">
                <xmacro_block name="geometry_mesh" uri="model://rmua19_standard_robot/meshes/gimbal_pitch.dae"/>
            </visual>
            <collision name="collision_main">
                <pose>0.015 0 0 0 0 0</pose>
                <xmacro_block name="geometry_box"  x="0.1" y="0.0915" z="0.08"/>
            </collision>
            <collision name="collision_box">
                <pose>-0.011 0 0.043 0 0 0</pose>
                <xmacro_block name="geometry_box"  x="0.14801" y="0.07" z="0.065"/>
            </collision>
            <sensor name="gimbal_imu" type="imu" >
                <always_on>1</always_on>
                <update_rate>200</update_rate>
            </sensor>
        </link>
        <!--for referee system -->
        <!--front armors -->
        <xmacro_block name="small_armor_with_support" suffix="_0" parent="chassis"  
                sticker_type="${sticker_type}" pose="0.197 0 0.061 0 0 0"/>
        <!--left armors -->
        <xmacro_block name="small_armor_with_support" suffix="_1" parent="chassis" 
                sticker_type="${sticker_type}" pose="0 0.116 0.061 0 0 1.5708"/>
        <!--rear armors -->
        <xmacro_block name="small_armor_with_support" suffix="_2" parent="chassis" 
                sticker_type="${sticker_type}" pose="-0.197 0 0.061 0 0 3.14"/>
        <!--right armors -->
        <xmacro_block name="small_armor_with_support" suffix="_3" parent="chassis" 
                sticker_type="${sticker_type}" pose="0 -0.116 0.061 0 0 -1.5708"/>
        <!--light_indicator-->
        <xmacro_block name="light_indicator" suffix="" parent="chassis" pose="-0.207 0 0.1 0 0 0"/>
        <!--speed_monitor_17mm-->
        <xmacro_block name="speed_monitor_17mm" suffix="" parent="gimbal_pitch" pose="0.07 0 0 0 0 0"/>
    </xmacro_define_block>
</sdf>