<?xml version="1.0" encoding="utf-8"?>

<robot xmlns:xacro="http://www.ros.org/wiki/xacro">

    <xacro:property name="threshold" value="0.08"/>
    <xacro:property name="pitch_lower_limit" value="-0.72"/>
    <xacro:property name="pitch_upper_limit" value="0.457"/>

    <link name="yaw">
        <inertial>
            <mass value="0.2"/>
            <origin xyz="-0.034 0.002 0.036"/>
            <inertia ixx="4.878e-4" ixy="1.941e-5" ixz="2.44e-4" iyy="8.322e-4"
                     iyz="-1.812e-5" izz="4.513e-4"/>
        </inertial>
        <visual>
            <origin xyz="0 0 0" rpy="0 0 0"/>
            <geometry>
                <mesh filename="package://robot_description/meshes/standard/yaw.stl" scale="0.001 0.001 0.001"/>
            </geometry>
        </visual>
        <collision>
            <origin xyz="0 0 0" rpy="0 0 0"/>
            <geometry>
                <mesh filename="package://robot_description/meshes/standard/yaw.stl" scale="0.001 0.001 0.001"/>
            </geometry>
        </collision>
    </link>

    <joint name="yaw_joint" type="revolute">
        <origin xyz="0 0 0.162"
                rpy="0 0 0"/>
        <dynamics damping="0.0" friction="0.1"/>
        <limit effort="1.2" velocity="31" lower="-1e10" upper="1e10"/>
        <parent link="base_link"/>
        <child link="yaw"/>
        <axis xyz="0 0 1"/>
    </joint>

    <link name="supply_frame"/>
    <joint name="supply_joint" type="fixed">
        <origin xyz="0 0 0" rpy="0 0 ${pi/3}"/>
        <parent link="yaw"/>
        <child link="supply_frame"/>
    </joint>

    <link name="pitch">
        <inertial>
            <mass value="0.644"/>
            <origin xyz="0.029 0.000617 0.0376"/>
            <inertia ixx="1.8216e-3" ixy="5.514e-6" ixz="1.58e-4" iyy="5.68e-3"
                     iyz="-6.628e-6" izz="4.396e-3"/>
        </inertial>
        <visual>
            <origin xyz="0 0 0" rpy="0 0 0"/>
            <geometry>
                <mesh filename="package://robot_description/meshes/standard/pitch.stl" scale="0.001 0.001 0.001"/>
            </geometry>
        </visual>
        <collision>
            <origin xyz="0 0 0" rpy="0 0 0"/>
            <geometry>
                <mesh filename="package://robot_description/meshes/standard/pitch.stl" scale="0.001 0.001 0.001"/>
            </geometry>
        </collision>
    </link>

    <joint name="pitch_joint" type="revolute">
        <origin xyz="0 0 0.09" rpy="0 0 0"/>
        <dynamics damping="0.0" friction="0.1"/>
        <limit effort="3." velocity="86" lower="${pitch_lower_limit}" upper="${pitch_upper_limit}"/>
        <safety_controller k_position="100" k_velocity="0.1"
                           soft_lower_limit="${pitch_lower_limit+threshold}"
                           soft_upper_limit="${pitch_upper_limit-threshold}"/>
        <parent link="yaw"/>
        <child link="pitch"/>
        <axis xyz="0 1 0 "/>
    </joint>

</robot>
