<?xml version="1.0" encoding="utf-8"?>
<robot xmlns:xacro="http://www.ros.org/wiki/xacro">

    <xacro:property name="threshold" value="0.05"/>
    <xacro:property name="pitch_lower_limit" value="-1.4"/>
    <xacro:property name="pitch_upper_limit" value="0.4"/>

    <link name="yaw">
        <inertial>
            <mass value="3.362534"/>
            <origin xyz="-0.048138 0.035027 0.064443"/>
            <inertia ixx="5.361E-02" ixy="-1.810E-03" ixz="1.319E-02" iyy="4.651E-02"
                     iyz="1.298E-02" izz="2.967E-02"/>
        </inertial>
        <visual>
            <origin xyz="0 0 0" rpy="0 0 0"/>
            <geometry>
                <mesh filename="package://robot_description/meshes/hero/yaw.stl" scale="0.001 0.001 0.001"/>
            </geometry>
        </visual>
        <collision>
            <origin xyz="0 0 0" rpy="0 0 0"/>
            <geometry>
                <mesh filename="package://robot_description/meshes/hero/yaw.stl" scale="0.001 0.001 0.001"/>
            </geometry>
        </collision>
    </link>

    <joint name="yaw_joint" type="revolute">
        <origin xyz="0 0 0.184"
                rpy="0 0 0"/>
        <dynamics damping="0.0" friction="0.1"/>
        <limit effort="1.2" velocity="13.82" lower="-1E10" upper="1E10"/>
        <parent link="base_link"/>
        <child link="yaw"/>
        <axis xyz="0 0 1"/>
    </joint>

    <link name="pitch">
        <inertial>
            <mass value="1.183148"/>
            <origin xyz="0.085638 0.00023 0.047017"/>
            <inertia ixx="2.934E-03" ixy="3.462E-05" ixz="1.834E-03" iyy="9.223E-03"
                     iyz="-0.422E-05" izz="8.072E-03"/>
        </inertial>
        <visual>
            <origin xyz="0 0 0" rpy="0 0 0"/>
            <geometry>
                <mesh filename="package://robot_description/meshes/hero/pitch.stl" scale="0.001 0.001 0.001"/>
            </geometry>
        </visual>
        <collision>
            <origin xyz="0 0 0" rpy="0 0 0"/>
            <geometry>
                <mesh filename="package://robot_description/meshes/hero/pitch.stl" scale="0.001 0.001 0.001"/>
            </geometry>
        </collision>
    </link>

    <joint name="pitch_joint" type="revolute">
        <origin xyz="-0.05 0 0.151" rpy="0 0 0"/>
        <dynamics damping="0.0" friction="0.1"/>
        <limit effort="1.2" velocity="13.82" lower="${pitch_lower_limit}" upper="${pitch_upper_limit}"/>
        <safety_controller k_velocity="0.1"
                           k_position="100"
                           soft_lower_limit="${pitch_lower_limit+threshold}"
                           soft_upper_limit="${pitch_upper_limit-threshold}"/>
        <parent link="yaw"/>
        <child link="pitch"/>
        <axis xyz="0 1 0 "/>
    </joint>


</robot>
