<?xml version="1.0" encoding="utf-8"?>
<robot xmlns:xacro="http://www.ros.org/wiki/xacro">

    <xacro:property name="threshold" value="0.1"/>
    <xacro:property name="pitch_lower_limit" value="-0.6"/>
    <xacro:property name="pitch_upper_limit" value="0.457"/>
    <xacro:property name="yaw_lower_limit" value="-0.627"/>
    <xacro:property name="yaw_upper_limit" value="0.627"/>

    <link name="yaw">
        <inertial>
            <mass value="0.568477"/>
            <origin xyz="-0.069988 -0.007741 -0.038882"/>
            <inertia ixx="1.216e-3" ixy="-3.509e-4" ixz="-1.522e-3" iyy="4.338e-3"
                     iyz="-1.557e-4" izz="3.37e-3"/>
        </inertial>
        <visual>
            <origin xyz="0 0 0" rpy="0 0 0"/>
            <geometry>
                <mesh filename="package://robot_description/meshes/drone/yaw.stl" scale="0.001 0.001 0.001"/>
            </geometry>
        </visual>
        <collision>
            <origin xyz="0 0 0" rpy="0 0 0"/>
            <geometry>
                <mesh filename="package://robot_description/meshes/drone/yaw.stl" scale="0.001 0.001 0.001"/>
            </geometry>
        </collision>
    </link>

    <joint name="yaw_joint" type="revolute">
        <origin xyz="0 0 -0.1"
                rpy="0 0 0"/>
        <dynamics damping="0.0" friction="0.1"/>
        <limit effort="1.2" velocity="31" lower="-1e10" upper="1e10"/>
        <safety_controller k_position="100" k_velocity="0.1"
                           soft_lower_limit="${yaw_lower_limit+threshold}"
                           soft_upper_limit="${yaw_upper_limit-threshold}"/>
        <parent link="base_link"/>
        <child link="yaw"/>
        <axis xyz="0 0 1"/>
    </joint>

    <link name="pitch">
        <inertial>
            <mass value="0.609754"/>
            <origin xyz="0.030701 0.00002 -0.03724"/>
            <inertia ixx="1.704e-03" ixy="-7.08992e-07" ixz="-2.916e-04" iyy="5.587e-03"
                     iyz="-1.02674e-06" izz="4.379e-03"/>
        </inertial>
        <visual>
            <origin xyz="0 0 0" rpy="0 0 0"/>
            <geometry>
                <mesh filename="package://robot_description/meshes/drone/pitch.stl" scale="0.001 0.001 0.001"/>
            </geometry>
        </visual>
        <collision>
            <origin xyz="0 0 0" rpy="0 0 0"/>
            <geometry>
                <mesh filename="package://robot_description/meshes/drone/pitch.stl" scale="0.001 0.001 0.001"/>
            </geometry>
        </collision>
    </link>

    <joint name="pitch_joint" type="revolute">
        <origin xyz="0 0 -0.09" rpy="0 0 0"/>
        <dynamics damping="0.0" friction="0.1"/>
        <limit effort="3.0" velocity="86" lower="${pitch_lower_limit}" upper="${pitch_upper_limit}"/>
        <safety_controller k_position="100" k_velocity="0.1"
                           soft_lower_limit="${pitch_lower_limit+threshold}"
                           soft_upper_limit="${pitch_upper_limit-threshold}"/>
        <parent link="yaw"/>
        <child link="pitch"/>
        <axis xyz="0 1 0 "/>
    </joint>

</robot>
