<?xml version="1.0" encoding="utf-8"?>

<robot xmlns:xacro="http://www.ros.org/wiki/xacro">

    <xacro:include filename="$(find robot_description)/urdf/common/friction.urdf.xacro"/>

    <xacro:property name="wheel_offset_x" value="0.047"/>
    <xacro:property name="wheel_offset_y" value="0.0365"/>
    <xacro:property name="wheel_offset_z" value="0.0004"/>

    <xacro:friction_wheel prefixs="left" connected_to="pitch"
                          wheel_x_offset="${wheel_offset_x}" wheel_y_offset="${wheel_offset_y}"
                          wheel_z_offset="${wheel_offset_z}"/>

    <xacro:friction_wheel prefixs="right" connected_to="pitch"
                          wheel_x_offset="${wheel_offset_x}" wheel_y_offset="${-wheel_offset_y}"
                          wheel_z_offset="${wheel_offset_z}"/>

    <link name="trigger">
        <inertial>
            <mass value="0.337277"/>
            <origin xyz="-0.023009 0.00007 0.005629"/>
            <inertia ixx="2.845e-04" ixy="-4.44764e-7" ixz="-1.044e-04" iyy="8.755e-04"
                     iyz="1.12179e-7" izz="8.681e-04"/>
        </inertial>
        <visual>
            <origin xyz="0 0 0" rpy="0 0 0"/>
            <geometry>
                <mesh filename="package://robot_description/meshes/drone/trigger.stl" scale="0.001 0.001 0.001"/>
            </geometry>
        </visual>
        <collision>
            <origin xyz="0 0 0" rpy="0 0 0"/>
            <geometry>
                <mesh filename="package://robot_description/meshes/drone/trigger.stl" scale="0.001 0.001 0.001"/>
            </geometry>
        </collision>
    </link>

    <joint name="trigger_joint" type="revolute">
        <origin xyz="0 0 -0.044" rpy="0 0 0"/>
        <dynamics damping="0.0" friction="0.01"/>
        <limit effort="3.0" velocity="43.54" lower="-1e16" upper="1e16"/>
        <parent link="base_link"/>
        <child link="trigger"/>
        <axis xyz="0 0 -1"/>
    </joint>

</robot>
