<?xml version="1.0" encoding="utf-8"?>

<robot xmlns:xacro="http://www.ros.org/wiki/xacro">

    <xacro:macro name="swerve_drive"
                 params="prefix x_offset y_offset z_offset  connected_to">

        <link name="${prefix}_pivot">
            <visual>
                <origin xyz="0 0 0" rpy="0 0 0"/>
                <geometry>
                    <mesh filename="package://robot_description/meshes/common/swerve_pivot.stl"
                          scale="0.001 0.001 0.001"/>
                </geometry>
            </visual>
            <inertial>
                <mass value="0.114131"/>
                <origin xyz="-0.00005 0.017079 -0.041536" rpy="0 0 0"/>
                <inertia ixx="1.335e-4" ixy="26.001e-9" ixz="65.031e-9" iyy="1.372e-4" iyz="20051.742e-9"
                         izz="66866.081e-9"/>
            </inertial>
        </link>

        <joint name="${prefix}_pivot_joint" type="revolute">
            <axis xyz="0 0 1"/>
            <origin xyz="${x_offset} ${y_offset} ${z_offset}" rpy="0 0 0"/>
            <parent link="${connected_to}"/>
            <child link="${prefix}_pivot"/>
            <dynamics damping="0.0" friction="0.1"/>
            <limit effort="1.2" velocity="50" lower="-1e10" upper="1e10"/>
        </joint>


        <link name="${prefix}_wheel">
            <visual>
                <origin xyz="0 0 0" rpy="0 0 0"/>
                <geometry>
                    <mesh filename="package://robot_description/meshes/common/swerve_wheel.stl"
                          scale="0.001 0.001 0.001"/>
                </geometry>
            </visual>
            <inertial>
                <mass value="0.267401"/>
                <origin xyz="-0.000004 0.000125 0.000001" rpy="0 0 0"/>
                <inertia ixx="3.585e-4" ixy="0" ixz="13.459e-9" iyy="6.846e-4" iyz="0"
                         izz="3.584e-4"/>
            </inertial>
            <collision>
                <origin xyz="0 0 0" rpy="${pi/2.} 0 0"/>
                <geometry>
                    <cylinder length="0.02" radius="0.055"/>
                </geometry>
            </collision>
        </link>

        <joint name="${prefix}_wheel_joint" type="revolute">
            <axis xyz="0 1 0"/>
            <origin xyz="0 0 -0.06635" rpy="0 0 0"/>
            <parent link="${prefix}_pivot"/>
            <child link="${prefix}_wheel"/>
            <limit effort="3" velocity="76" lower="-1e10" upper="1e10"/>
            <dynamics damping="0.0" friction="0.05"/>
        </joint>

        <gazebo reference="${prefix}_wheel">
            <mu1 value="1.0"/>
            <mu2 value="1.0"/>
            <kp value="1000000.0"/>
            <kd value="100.0"/>
            <material>Gazebo/Black</material>
        </gazebo>
    </xacro:macro>

    <xacro:macro name="swerve_transmission" params="prefix wheel_reduction  pivot_offset">

        <transmission name="${prefix}_pivot_trans">
            <type>transmission_interface/SimpleTransmission</type>
            <actuator name="${prefix}_pivot_motor">
                <mechanicalReduction>-1</mechanicalReduction>
            </actuator>
            <joint name="${prefix}_pivot_joint">
                <offset>${pivot_offset}</offset>
                <hardwareInterface>hardware_interface/EffortJointInterface</hardwareInterface>
            </joint>
        </transmission>

        <transmission name="${prefix}_wheel_trans">
            <type>transmission_interface/SimpleTransmission</type>
            <actuator name="${prefix}_wheel_motor">
                <mechanicalReduction>${wheel_reduction}</mechanicalReduction>
            </actuator>
            <joint name="${prefix}_wheel_joint">
                <hardwareInterface>hardware_interface/EffortJointInterface</hardwareInterface>
            </joint>
        </transmission>
    </xacro:macro>

</robot>
