<?xml version="1.0" ?>
<!-- =================================================================================== -->
<!-- |    This document was autogenerated by xmacro4sdf from model.sdf.xmacro          | -->
<!-- |    EDITING THIS FILE BY HAND IS NOT RECOMMENDED                                 | -->
<!-- =================================================================================== -->
<sdf version="1.7">
	<!--include defination-->
	<!--property defination-->
	<!--rmua19_standard_robot model-->
	<model name="rmua19_standard_robot">
		<pose>0 0 0.15 0 0 0</pose>
		<!--chassis-->
		<link name="chassis">
			<inertial>
				<pose>0 0 0.055 0 0 0</pose>
				<mass>15.0</mass>
				<inertia>
					<ixx>0.093125</ixx>
					<ixy>0</ixy>
					<ixz>0</ixz>
					<iyy>0.18312499999999998</iyy>
					<iyz>0</iyz>
					<izz>0.23399999999999999</izz>
				</inertia>
			</inertial>
			<visual name="chassis_visual">
				<geometry>
					<mesh>
						<uri>model://rmua19_standard_robot/meshes/chassis_base.dae</uri>
					</mesh>
				</geometry>
			</visual>
			<collision name="chassis_base_collision">
				<pose>0 0 0.045 0 0 0</pose>
				<geometry>
					<box>
						<size>0.36 0.24 0.13</size>
					</box>
				</geometry>
			</collision>
			<collision name="chassis_projectile_container_collision">
				<pose>-0.122 0 0.177 0 0 0</pose>
				<geometry>
					<box>
						<size>0.1 0.18 0.146</size>
					</box>
				</geometry>
			</collision>
			<collision name="chassis_fornt_wheel_holder_collision">
				<pose>0.208 0 0 0 0 0</pose>
				<geometry>
					<box>
						<size>0.055 0.367 0.055</size>
					</box>
				</geometry>
			</collision>
			<collision name="chassis_rear_wheel_holder_collision">
				<pose>-0.208 0 0 0 0 0</pose>
				<geometry>
					<box>
						<size>0.055 0.367 0.055</size>
					</box>
				</geometry>
			</collision>
			<sensor name="chassis_imu" type="imu">
				<always_on>1</always_on>
				<update_rate>200</update_rate>
			</sensor>
		</link>
		<!--front_left wheel link and joint-->
		<joint name="front_left_wheel_joint" type="revolute">
			<pose relative_to="chassis">0.207 0.194 0 0 0 0</pose>
			<parent>chassis</parent>
			<child>front_left_wheel</child>
			<axis>
				<xyz>0 1 0</xyz>
				<limit>
					<lower>-1.79769e+308</lower>
					<upper>1.79769e+308</upper>
				</limit>
			</axis>
		</joint>
		<link name="front_left_wheel">
			<pose relative_to="front_left_wheel_joint">0 0 0 0 0 0</pose>
			<inertial>
				<pose>0 0 0 1.5707 0 0</pose>
				<mass>0.4</mass>
				<inertia>
					<ixx>0.0006426653333333334</ixx>
					<ixy>0</ixy>
					<ixz>0</ixz>
					<iyy>0.0006426653333333334</iyy>
					<iyz>0</iyz>
					<izz>0.0011491280000000001</izz>
				</inertia>
			</inertial>
			<visual name="front_left_wheel_visual">
				<geometry>
					<mesh>
						<uri>model://rmua19_standard_robot/meshes/wheel_left.dae</uri>
					</mesh>
				</geometry>
			</visual>
			<collision name="front_left_wheel_collision">
				<pose>0 0 0 1.5707 0 0</pose>
				<geometry>
					<cylinder>
						<radius>0.0758</radius>
						<length>0.0452</length>
					</cylinder>
				</geometry>
				<surface>
					<friction>
						<ode>
							<mu>0.2</mu>
							<mu2>0.2</mu2>
						</ode>
					</friction>
				</surface>
			</collision>
		</link>
		<!--front_right wheel link and joint-->
		<joint name="front_right_wheel_joint" type="revolute">
			<pose relative_to="chassis">0.207 -0.194 0 0 0 0</pose>
			<parent>chassis</parent>
			<child>front_right_wheel</child>
			<axis>
				<xyz>0 1 0</xyz>
				<limit>
					<lower>-1.79769e+308</lower>
					<upper>1.79769e+308</upper>
				</limit>
			</axis>
		</joint>
		<link name="front_right_wheel">
			<pose relative_to="front_right_wheel_joint">0 0 0 0 0 0</pose>
			<inertial>
				<pose>0 0 0 1.5707 0 0</pose>
				<mass>0.4</mass>
				<inertia>
					<ixx>0.0006426653333333334</ixx>
					<ixy>0</ixy>
					<ixz>0</ixz>
					<iyy>0.0006426653333333334</iyy>
					<iyz>0</iyz>
					<izz>0.0011491280000000001</izz>
				</inertia>
			</inertial>
			<visual name="front_right_wheel_visual">
				<geometry>
					<mesh>
						<uri>model://rmua19_standard_robot/meshes/wheel_right.dae</uri>
					</mesh>
				</geometry>
			</visual>
			<collision name="front_right_wheel_collision">
				<pose>0 0 0 1.5707 0 0</pose>
				<geometry>
					<cylinder>
						<radius>0.0758</radius>
						<length>0.0452</length>
					</cylinder>
				</geometry>
				<surface>
					<friction>
						<ode>
							<mu>0.2</mu>
							<mu2>0.2</mu2>
						</ode>
					</friction>
				</surface>
			</collision>
		</link>
		<!--rear_left wheel link and joint-->
		<joint name="rear_left_wheel_joint" type="revolute">
			<pose relative_to="chassis">-0.207 0.194 0 0 0 0</pose>
			<parent>chassis</parent>
			<child>rear_left_wheel</child>
			<axis>
				<xyz>0 1 0</xyz>
				<limit>
					<lower>-1.79769e+308</lower>
					<upper>1.79769e+308</upper>
				</limit>
			</axis>
		</joint>
		<link name="rear_left_wheel">
			<pose relative_to="rear_left_wheel_joint">0 0 0 0 0 0</pose>
			<inertial>
				<pose>0 0 0 1.5707 0 0</pose>
				<mass>0.4</mass>
				<inertia>
					<ixx>0.0006426653333333334</ixx>
					<ixy>0</ixy>
					<ixz>0</ixz>
					<iyy>0.0006426653333333334</iyy>
					<iyz>0</iyz>
					<izz>0.0011491280000000001</izz>
				</inertia>
			</inertial>
			<visual name="rear_left_wheel_visual">
				<geometry>
					<mesh>
						<uri>model://rmua19_standard_robot/meshes/wheel_right.dae</uri>
					</mesh>
				</geometry>
			</visual>
			<collision name="rear_left_wheel_collision">
				<pose>0 0 0 1.5707 0 0</pose>
				<geometry>
					<cylinder>
						<radius>0.0758</radius>
						<length>0.0452</length>
					</cylinder>
				</geometry>
				<surface>
					<friction>
						<ode>
							<mu>0.2</mu>
							<mu2>0.2</mu2>
						</ode>
					</friction>
				</surface>
			</collision>
		</link>
		<!--rear_right wheel link and joint-->
		<joint name="rear_right_wheel_joint" type="revolute">
			<pose relative_to="chassis">-0.207 -0.194 0 0 0 0</pose>
			<parent>chassis</parent>
			<child>rear_right_wheel</child>
			<axis>
				<xyz>0 1 0</xyz>
				<limit>
					<lower>-1.79769e+308</lower>
					<upper>1.79769e+308</upper>
				</limit>
			</axis>
		</joint>
		<link name="rear_right_wheel">
			<pose relative_to="rear_right_wheel_joint">0 0 0 0 0 0</pose>
			<inertial>
				<pose>0 0 0 1.5707 0 0</pose>
				<mass>0.4</mass>
				<inertia>
					<ixx>0.0006426653333333334</ixx>
					<ixy>0</ixy>
					<ixz>0</ixz>
					<iyy>0.0006426653333333334</iyy>
					<iyz>0</iyz>
					<izz>0.0011491280000000001</izz>
				</inertia>
			</inertial>
			<visual name="rear_right_wheel_visual">
				<geometry>
					<mesh>
						<uri>model://rmua19_standard_robot/meshes/wheel_left.dae</uri>
					</mesh>
				</geometry>
			</visual>
			<collision name="rear_right_wheel_collision">
				<pose>0 0 0 1.5707 0 0</pose>
				<geometry>
					<cylinder>
						<radius>0.0758</radius>
						<length>0.0452</length>
					</cylinder>
				</geometry>
				<surface>
					<friction>
						<ode>
							<mu>0.2</mu>
							<mu2>0.2</mu2>
						</ode>
					</friction>
				</surface>
			</collision>
		</link>
		<!--gimbal yaw module-->
		<joint name="gimbal_yaw_joint" type="revolute">
			<pose relative_to="chassis">0 0 0.1376 0 0 0</pose>
			<parent>chassis</parent>
			<child>gimbal_yaw</child>
			<axis>
				<xyz>0 0 1</xyz>
				<limit>
					<lower>-1.57</lower>
					<upper>1.57</upper>
				</limit>
			</axis>
		</joint>
		<link name="gimbal_yaw">
			<pose relative_to="gimbal_yaw_joint">0 0 0 0 0 0</pose>
			<inertial>
				<pose>0 0 0.06 0 0 0</pose>
				<mass>1.0</mass>
				<inertia>
					<ixx>0.003033333333333334</ixx>
					<ixy>0</ixy>
					<ixz>0</ixz>
					<iyy>0.003033333333333334</iyy>
					<iyz>0</iyz>
					<izz>0.0012500000000000002</izz>
				</inertia>
			</inertial>
			<visual name="visual">
				<geometry>
					<mesh>
						<uri>model://rmua19_standard_robot/meshes/gimbal_yaw.dae</uri>
					</mesh>
				</geometry>
			</visual>
			<collision name="collision">
				<pose>0 0 0.0885 0 0 0</pose>
				<geometry>
					<box>
						<size>0.065 0.117 0.177</size>
					</box>
				</geometry>
			</collision>
		</link>
		<!--gimbal pitch module-->
		<joint name="gimbal_pitch_joint" type="revolute">
			<pose relative_to="gimbal_yaw">0 0.004 0.16 0 0 0</pose>
			<parent>gimbal_yaw</parent>
			<child>gimbal_pitch</child>
			<axis>
				<xyz>0 1 0</xyz>
				<limit>
					<lower>-0.785</lower>
					<upper>0.5652</upper>
				</limit>
			</axis>
		</joint>
		<link name="gimbal_pitch">
			<pose relative_to="gimbal_pitch_joint">0 0 0 0 0 0</pose>
			<inertial>
				<pose>0.02 0 0 0 0 0</pose>
				<mass>0.5</mass>
				<inertia>
					<ixx>0.0007541666666666668</ixx>
					<ixy>0</ixy>
					<ixz>0</ixz>
					<iyy>0.0030208333333333337</iyy>
					<iyz>0</iyz>
					<izz>0.0029416666666666666</izz>
				</inertia>
			</inertial>
			<visual name="visual">
				<geometry>
					<mesh>
						<uri>model://rmua19_standard_robot/meshes/gimbal_pitch.dae</uri>
					</mesh>
				</geometry>
			</visual>
			<collision name="collision_main">
				<pose>0.015 0 0 0 0 0</pose>
				<geometry>
					<box>
						<size>0.1 0.0915 0.08</size>
					</box>
				</geometry>
			</collision>
			<collision name="collision_box">
				<pose>-0.011 0 0.043 0 0 0</pose>
				<geometry>
					<box>
						<size>0.14801 0.07 0.065</size>
					</box>
				</geometry>
			</collision>
			<sensor name="gimbal_imu" type="imu">
				<always_on>1</always_on>
				<update_rate>200</update_rate>
			</sensor>
		</link>
		<!--for referee system -->
		<!--front armors -->
		<joint name="armor_support_frame_0_joint" type="fixed">
			<pose relative_to="chassis">0.197 0 0.061 0 0 0</pose>
			<parent>chassis</parent>
			<child>armor_support_frame_0</child>
		</joint>
		<link name="armor_support_frame_0">
			<pose relative_to="armor_support_frame_0_joint">0 0 0 0 0 0</pose>
			<inertial>
				<pose>0.035 0 0 0 0 0</pose>
				<mass>0.1</mass>
				<inertia>
					<ixx>0.00023080833333333334</ixx>
					<ixy>0</ixy>
					<ixz>0</ixz>
					<iyy>0.00017014166666666668</iyy>
					<iyz>0</iyz>
					<izz>0.00014468333333333334</izz>
				</inertia>
			</inertial>
			<visual name="visual">
				<geometry>
					<mesh>
						<uri>model://rm21_armor_module/meshes/armor_support_frame.stl</uri>
					</mesh>
				</geometry>
				<material>
					<ambient>0.1 0.1 0.1</ambient>
					<diffuse>0.05 0.05 0.05</diffuse>
					<specular>0.6 0.6 0.6</specular>
				</material>
			</visual>
			<collision name="collision">
				<pose>0.015 0 0 0 0 0</pose>
				<geometry>
					<box>
						<size>0.03 0.11 0.08</size>
					</box>
				</geometry>
			</collision>
		</link>
		<joint name="armor_0_joint" type="fixed">
			<pose relative_to="armor_support_frame_0">0.075 0 -0.071 0 -0.262 0</pose>
			<parent>armor_support_frame_0</parent>
			<child>armor_0</child>
		</joint>
		<link name="armor_0">
			<pose relative_to="armor_0_joint">0 0 0 0 0 0</pose>
			<inertial>
				<pose>0 0 0.0625 0 0 0</pose>
				<mass>0.1</mass>
				<inertia>
					<ixx>0.0003065083333333333</ixx>
					<ixy>0</ixy>
					<ixz>0</ixz>
					<iyy>0.0001421774166666667</iyy>
					<iyz>0</iyz>
					<izz>0.0001670190833333333</izz>
				</inertia>
			</inertial>
			<visual name="visual">
				<geometry>
					<mesh>
						<uri>model://rm21_armor_module/meshes/small_armor.dae</uri>
					</mesh>
				</geometry>
				<material>
					<ambient>0.1 0.1 0.1</ambient>
					<diffuse>0.05 0.05 0.05</diffuse>
					<specular>0.6 0.6 0.6</specular>
				</material>
			</visual>
			<visual name="target_visual">
				<geometry>
					<mesh>
						<uri>model://rm21_armor_module/meshes/small_armor_target.dae</uri>
					</mesh>
				</geometry>
				<material>
					<ambient>0.1 0.1 0.1</ambient>
					<diffuse>0.05 0.05 0.05</diffuse>
					<specular>0.6 0.6 0.6</specular>
				</material>
			</visual>
			<visual name="light_bar_visual">
				<geometry>
					<mesh>
						<uri>model://rm21_armor_module/meshes/small_armor_light_bar.dae</uri>
					</mesh>
				</geometry>
				<material>
					<ambient>1.0 1.0 1.0</ambient>
					<diffuse>1.0 1.0 1.0</diffuse>
					<specular>0.5 0.5 0.5</specular>
				</material>
			</visual>
			<visual name="sticker_visual">
				<pose>0.014 0 0.0625 1.5708 0 1.5708</pose>
				<geometry>
					<plane>
						<normal>0 0 1</normal>
						<size>0.130 0.120</size>
					</plane>
				</geometry>
				<material>
					<ambient>1.0 1.0 1.0</ambient>
					<diffuse>1.0 1.0 1.0</diffuse>
					<specular>0.1 0.1 0.1</specular>
					<pbr>
						<metal>
							<albedo_map>model://rm21_armor_module/materials/textures/small_num1.png</albedo_map>
						</metal>
					</pbr>
				</material>
			</visual>
			<collision name="collision">
				<pose>0 0 0.0625 0 0 0</pose>
				<geometry>
					<box>
						<size>0.013 0.135 0.125</size>
					</box>
				</geometry>
			</collision>
			<collision name="target_collision">
				<pose>0.012 0 0.0625 0 0 0</pose>
				<geometry>
					<box>
						<size>0.008 0.135 0.125</size>
					</box>
				</geometry>
			</collision>
		</link>
		<!--left armors -->
		<joint name="armor_support_frame_1_joint" type="fixed">
			<pose relative_to="chassis">0 0.116 0.061 0 0 1.5708</pose>
			<parent>chassis</parent>
			<child>armor_support_frame_1</child>
		</joint>
		<link name="armor_support_frame_1">
			<pose relative_to="armor_support_frame_1_joint">0 0 0 0 0 0</pose>
			<inertial>
				<pose>0.035 0 0 0 0 0</pose>
				<mass>0.1</mass>
				<inertia>
					<ixx>0.00023080833333333334</ixx>
					<ixy>0</ixy>
					<ixz>0</ixz>
					<iyy>0.00017014166666666668</iyy>
					<iyz>0</iyz>
					<izz>0.00014468333333333334</izz>
				</inertia>
			</inertial>
			<visual name="visual">
				<geometry>
					<mesh>
						<uri>model://rm21_armor_module/meshes/armor_support_frame.stl</uri>
					</mesh>
				</geometry>
				<material>
					<ambient>0.1 0.1 0.1</ambient>
					<diffuse>0.05 0.05 0.05</diffuse>
					<specular>0.6 0.6 0.6</specular>
				</material>
			</visual>
			<collision name="collision">
				<pose>0.015 0 0 0 0 0</pose>
				<geometry>
					<box>
						<size>0.03 0.11 0.08</size>
					</box>
				</geometry>
			</collision>
		</link>
		<joint name="armor_1_joint" type="fixed">
			<pose relative_to="armor_support_frame_1">0.075 0 -0.071 0 -0.262 0</pose>
			<parent>armor_support_frame_1</parent>
			<child>armor_1</child>
		</joint>
		<link name="armor_1">
			<pose relative_to="armor_1_joint">0 0 0 0 0 0</pose>
			<inertial>
				<pose>0 0 0.0625 0 0 0</pose>
				<mass>0.1</mass>
				<inertia>
					<ixx>0.0003065083333333333</ixx>
					<ixy>0</ixy>
					<ixz>0</ixz>
					<iyy>0.0001421774166666667</iyy>
					<iyz>0</iyz>
					<izz>0.0001670190833333333</izz>
				</inertia>
			</inertial>
			<visual name="visual">
				<geometry>
					<mesh>
						<uri>model://rm21_armor_module/meshes/small_armor.dae</uri>
					</mesh>
				</geometry>
				<material>
					<ambient>0.1 0.1 0.1</ambient>
					<diffuse>0.05 0.05 0.05</diffuse>
					<specular>0.6 0.6 0.6</specular>
				</material>
			</visual>
			<visual name="target_visual">
				<geometry>
					<mesh>
						<uri>model://rm21_armor_module/meshes/small_armor_target.dae</uri>
					</mesh>
				</geometry>
				<material>
					<ambient>0.1 0.1 0.1</ambient>
					<diffuse>0.05 0.05 0.05</diffuse>
					<specular>0.6 0.6 0.6</specular>
				</material>
			</visual>
			<visual name="light_bar_visual">
				<geometry>
					<mesh>
						<uri>model://rm21_armor_module/meshes/small_armor_light_bar.dae</uri>
					</mesh>
				</geometry>
				<material>
					<ambient>1.0 1.0 1.0</ambient>
					<diffuse>1.0 1.0 1.0</diffuse>
					<specular>0.5 0.5 0.5</specular>
				</material>
			</visual>
			<visual name="sticker_visual">
				<pose>0.014 0 0.0625 1.5708 0 1.5708</pose>
				<geometry>
					<plane>
						<normal>0 0 1</normal>
						<size>0.130 0.120</size>
					</plane>
				</geometry>
				<material>
					<ambient>1.0 1.0 1.0</ambient>
					<diffuse>1.0 1.0 1.0</diffuse>
					<specular>0.1 0.1 0.1</specular>
					<pbr>
						<metal>
							<albedo_map>model://rm21_armor_module/materials/textures/small_num1.png</albedo_map>
						</metal>
					</pbr>
				</material>
			</visual>
			<collision name="collision">
				<pose>0 0 0.0625 0 0 0</pose>
				<geometry>
					<box>
						<size>0.013 0.135 0.125</size>
					</box>
				</geometry>
			</collision>
			<collision name="target_collision">
				<pose>0.012 0 0.0625 0 0 0</pose>
				<geometry>
					<box>
						<size>0.008 0.135 0.125</size>
					</box>
				</geometry>
			</collision>
		</link>
		<!--rear armors -->
		<joint name="armor_support_frame_2_joint" type="fixed">
			<pose relative_to="chassis">-0.197 0 0.061 0 0 3.14</pose>
			<parent>chassis</parent>
			<child>armor_support_frame_2</child>
		</joint>
		<link name="armor_support_frame_2">
			<pose relative_to="armor_support_frame_2_joint">0 0 0 0 0 0</pose>
			<inertial>
				<pose>0.035 0 0 0 0 0</pose>
				<mass>0.1</mass>
				<inertia>
					<ixx>0.00023080833333333334</ixx>
					<ixy>0</ixy>
					<ixz>0</ixz>
					<iyy>0.00017014166666666668</iyy>
					<iyz>0</iyz>
					<izz>0.00014468333333333334</izz>
				</inertia>
			</inertial>
			<visual name="visual">
				<geometry>
					<mesh>
						<uri>model://rm21_armor_module/meshes/armor_support_frame.stl</uri>
					</mesh>
				</geometry>
				<material>
					<ambient>0.1 0.1 0.1</ambient>
					<diffuse>0.05 0.05 0.05</diffuse>
					<specular>0.6 0.6 0.6</specular>
				</material>
			</visual>
			<collision name="collision">
				<pose>0.015 0 0 0 0 0</pose>
				<geometry>
					<box>
						<size>0.03 0.11 0.08</size>
					</box>
				</geometry>
			</collision>
		</link>
		<joint name="armor_2_joint" type="fixed">
			<pose relative_to="armor_support_frame_2">0.075 0 -0.071 0 -0.262 0</pose>
			<parent>armor_support_frame_2</parent>
			<child>armor_2</child>
		</joint>
		<link name="armor_2">
			<pose relative_to="armor_2_joint">0 0 0 0 0 0</pose>
			<inertial>
				<pose>0 0 0.0625 0 0 0</pose>
				<mass>0.1</mass>
				<inertia>
					<ixx>0.0003065083333333333</ixx>
					<ixy>0</ixy>
					<ixz>0</ixz>
					<iyy>0.0001421774166666667</iyy>
					<iyz>0</iyz>
					<izz>0.0001670190833333333</izz>
				</inertia>
			</inertial>
			<visual name="visual">
				<geometry>
					<mesh>
						<uri>model://rm21_armor_module/meshes/small_armor.dae</uri>
					</mesh>
				</geometry>
				<material>
					<ambient>0.1 0.1 0.1</ambient>
					<diffuse>0.05 0.05 0.05</diffuse>
					<specular>0.6 0.6 0.6</specular>
				</material>
			</visual>
			<visual name="target_visual">
				<geometry>
					<mesh>
						<uri>model://rm21_armor_module/meshes/small_armor_target.dae</uri>
					</mesh>
				</geometry>
				<material>
					<ambient>0.1 0.1 0.1</ambient>
					<diffuse>0.05 0.05 0.05</diffuse>
					<specular>0.6 0.6 0.6</specular>
				</material>
			</visual>
			<visual name="light_bar_visual">
				<geometry>
					<mesh>
						<uri>model://rm21_armor_module/meshes/small_armor_light_bar.dae</uri>
					</mesh>
				</geometry>
				<material>
					<ambient>1.0 1.0 1.0</ambient>
					<diffuse>1.0 1.0 1.0</diffuse>
					<specular>0.5 0.5 0.5</specular>
				</material>
			</visual>
			<visual name="sticker_visual">
				<pose>0.014 0 0.0625 1.5708 0 1.5708</pose>
				<geometry>
					<plane>
						<normal>0 0 1</normal>
						<size>0.130 0.120</size>
					</plane>
				</geometry>
				<material>
					<ambient>1.0 1.0 1.0</ambient>
					<diffuse>1.0 1.0 1.0</diffuse>
					<specular>0.1 0.1 0.1</specular>
					<pbr>
						<metal>
							<albedo_map>model://rm21_armor_module/materials/textures/small_num1.png</albedo_map>
						</metal>
					</pbr>
				</material>
			</visual>
			<collision name="collision">
				<pose>0 0 0.0625 0 0 0</pose>
				<geometry>
					<box>
						<size>0.013 0.135 0.125</size>
					</box>
				</geometry>
			</collision>
			<collision name="target_collision">
				<pose>0.012 0 0.0625 0 0 0</pose>
				<geometry>
					<box>
						<size>0.008 0.135 0.125</size>
					</box>
				</geometry>
			</collision>
		</link>
		<!--right armors -->
		<joint name="armor_support_frame_3_joint" type="fixed">
			<pose relative_to="chassis">0 -0.116 0.061 0 0 -1.5708</pose>
			<parent>chassis</parent>
			<child>armor_support_frame_3</child>
		</joint>
		<link name="armor_support_frame_3">
			<pose relative_to="armor_support_frame_3_joint">0 0 0 0 0 0</pose>
			<inertial>
				<pose>0.035 0 0 0 0 0</pose>
				<mass>0.1</mass>
				<inertia>
					<ixx>0.00023080833333333334</ixx>
					<ixy>0</ixy>
					<ixz>0</ixz>
					<iyy>0.00017014166666666668</iyy>
					<iyz>0</iyz>
					<izz>0.00014468333333333334</izz>
				</inertia>
			</inertial>
			<visual name="visual">
				<geometry>
					<mesh>
						<uri>model://rm21_armor_module/meshes/armor_support_frame.stl</uri>
					</mesh>
				</geometry>
				<material>
					<ambient>0.1 0.1 0.1</ambient>
					<diffuse>0.05 0.05 0.05</diffuse>
					<specular>0.6 0.6 0.6</specular>
				</material>
			</visual>
			<collision name="collision">
				<pose>0.015 0 0 0 0 0</pose>
				<geometry>
					<box>
						<size>0.03 0.11 0.08</size>
					</box>
				</geometry>
			</collision>
		</link>
		<joint name="armor_3_joint" type="fixed">
			<pose relative_to="armor_support_frame_3">0.075 0 -0.071 0 -0.262 0</pose>
			<parent>armor_support_frame_3</parent>
			<child>armor_3</child>
		</joint>
		<link name="armor_3">
			<pose relative_to="armor_3_joint">0 0 0 0 0 0</pose>
			<inertial>
				<pose>0 0 0.0625 0 0 0</pose>
				<mass>0.1</mass>
				<inertia>
					<ixx>0.0003065083333333333</ixx>
					<ixy>0</ixy>
					<ixz>0</ixz>
					<iyy>0.0001421774166666667</iyy>
					<iyz>0</iyz>
					<izz>0.0001670190833333333</izz>
				</inertia>
			</inertial>
			<visual name="visual">
				<geometry>
					<mesh>
						<uri>model://rm21_armor_module/meshes/small_armor.dae</uri>
					</mesh>
				</geometry>
				<material>
					<ambient>0.1 0.1 0.1</ambient>
					<diffuse>0.05 0.05 0.05</diffuse>
					<specular>0.6 0.6 0.6</specular>
				</material>
			</visual>
			<visual name="target_visual">
				<geometry>
					<mesh>
						<uri>model://rm21_armor_module/meshes/small_armor_target.dae</uri>
					</mesh>
				</geometry>
				<material>
					<ambient>0.1 0.1 0.1</ambient>
					<diffuse>0.05 0.05 0.05</diffuse>
					<specular>0.6 0.6 0.6</specular>
				</material>
			</visual>
			<visual name="light_bar_visual">
				<geometry>
					<mesh>
						<uri>model://rm21_armor_module/meshes/small_armor_light_bar.dae</uri>
					</mesh>
				</geometry>
				<material>
					<ambient>1.0 1.0 1.0</ambient>
					<diffuse>1.0 1.0 1.0</diffuse>
					<specular>0.5 0.5 0.5</specular>
				</material>
			</visual>
			<visual name="sticker_visual">
				<pose>0.014 0 0.0625 1.5708 0 1.5708</pose>
				<geometry>
					<plane>
						<normal>0 0 1</normal>
						<size>0.130 0.120</size>
					</plane>
				</geometry>
				<material>
					<ambient>1.0 1.0 1.0</ambient>
					<diffuse>1.0 1.0 1.0</diffuse>
					<specular>0.1 0.1 0.1</specular>
					<pbr>
						<metal>
							<albedo_map>model://rm21_armor_module/materials/textures/small_num1.png</albedo_map>
						</metal>
					</pbr>
				</material>
			</visual>
			<collision name="collision">
				<pose>0 0 0.0625 0 0 0</pose>
				<geometry>
					<box>
						<size>0.013 0.135 0.125</size>
					</box>
				</geometry>
			</collision>
			<collision name="target_collision">
				<pose>0.012 0 0.0625 0 0 0</pose>
				<geometry>
					<box>
						<size>0.008 0.135 0.125</size>
					</box>
				</geometry>
			</collision>
		</link>
		<!--light_indicator-->
		<joint name="light_indicator_joint" type="fixed">
			<pose relative_to="chassis">-0.207 0 0.1 0 0 0</pose>
			<parent>chassis</parent>
			<child>light_indicator</child>
		</joint>
		<link name="light_indicator">
			<pose relative_to="light_indicator_joint">0 0 0 0 0 0</pose>
			<inertial>
				<pose>0 0 0.04 0 0 0</pose>
				<mass>0.1</mass>
				<inertia>
					<ixx>0.0006666666666666669</ixx>
					<ixy>0</ixy>
					<ixz>0</ixz>
					<iyy>3.416666666666667e-05</iyy>
					<iyz>0</iyz>
					<izz>0.0006741666666666668</izz>
				</inertia>
			</inertial>
			<visual name="light_indicator_holder_visual">
				<geometry>
					<mesh>
						<uri>model://rm21_light_indicator_module/meshes/light_indicator_holder.dae</uri>
					</mesh>
				</geometry>
				<material>
					<ambient>0.1 0.1 0.1</ambient>
					<diffuse>0.05 0.05 0.05</diffuse>
					<specular>0.6 0.6 0.6</specular>
				</material>
			</visual>
			<visual name="light_bar_visual">
				<geometry>
					<mesh>
						<uri>model://rm21_light_indicator_module/meshes/light_indicator_bar.dae</uri>
					</mesh>
				</geometry>
				<material>
					<ambient>1.0 1.0 1.0</ambient>
					<diffuse>1.0 1.0 1.0</diffuse>
					<specular>0.5 0.5 0.5</specular>
				</material>
			</visual>
			<collision name="light_bar_collision">
				<pose>0 0 0.06 0 0 0</pose>
				<geometry>
					<box>
						<size>0.05 0.28 0.04</size>
					</box>
				</geometry>
			</collision>
		</link>
		<!--speed_monitor_17mm-->
		<joint name="speed_monitor_joint" type="fixed">
			<pose relative_to="gimbal_pitch">0.07 0 0 0 0 0</pose>
			<parent>gimbal_pitch</parent>
			<child>speed_monitor</child>
		</joint>
		<link name="speed_monitor">
			<pose relative_to="speed_monitor_joint">0 0 0 0 0 0</pose>
			<inertial>
				<pose>0.055 0 0 0 0 0</pose>
				<mass>0.1</mass>
				<inertia>
					<ixx>2.941666666666667e-05</ixx>
					<ixy>0</ixy>
					<ixz>0</ixz>
					<iyy>0.00011484166666666668</iyy>
					<iyz>0</iyz>
					<izz>0.00011624166666666668</izz>
				</inertia>
			</inertial>
			<visual name="visual">
				<geometry>
					<mesh>
						<uri>model://rm21_speed_monitor_module/meshes/speed_monitor_17mm.dae</uri>
					</mesh>
				</geometry>
				<material>
					<ambient>0.1 0.1 0.1</ambient>
					<diffuse>0.05 0.05 0.05</diffuse>
					<specular>0.6 0.6 0.6</specular>
				</material>
			</visual>
			<visual name="light_bar_visual">
				<geometry>
					<mesh>
						<uri>model://rm21_speed_monitor_module/meshes/speed_monitor_17mm_light_bar.dae</uri>
					</mesh>
				</geometry>
				<material>
					<ambient>1.0 1.0 1.0</ambient>
					<diffuse>1.0 1.0 1.0</diffuse>
					<specular>0.5 0.5 0.5</specular>
				</material>
			</visual>
			<collision name="collision">
				<pose>0.055 0 0 0 0 0</pose>
				<geometry>
					<box>
						<size>0.11 0.043 0.041</size>
					</box>
				</geometry>
			</collision>
		</link>
		<!--plugins-->
		<!--plugin for light bar-->
		<plugin filename="LightBarController" name="ignition::gazebo::systems::LightBarController">
			<controller_name>color</controller_name>
			<link_visual>armor_0/light_bar_visual</link_visual>
			<link_visual>armor_1/light_bar_visual</link_visual>
			<link_visual>armor_2/light_bar_visual</link_visual>
			<link_visual>armor_3/light_bar_visual</link_visual>
			<link_visual>light_indicator/light_bar_visual</link_visual>
			<link_visual>speed_monitor/light_bar_visual</link_visual>
			<initial_color>none</initial_color>
		</plugin>
		<!--plugin for joint state sensor-->
		<plugin filename="ignition-gazebo-joint-state-publisher-system" name="ignition::gazebo::systems::JointStatePublisher">
			<joint_name>gimbal_yaw_joint</joint_name>
			<joint_name>gimbal_pitch_joint</joint_name>
		</plugin>
		<!--plugin for chassis control-->
		<plugin filename="MecanumDrive2" name="ignition::gazebo::systems::MecanumDrive2">
			<chassis_link>chassis</chassis_link>
			<front_left_joint>front_left_wheel_joint</front_left_joint>
			<front_right_joint>front_right_wheel_joint</front_right_joint>
			<rear_left_joint>rear_left_wheel_joint</rear_left_joint>
			<rear_right_joint>rear_right_wheel_joint</rear_right_joint>
		</plugin>
		<!--plugin for gimbal control-->
		<plugin filename="ignition-gazebo-joint-position-controller-system" name="ignition::gazebo::systems::JointPositionController">
			<joint_name>gimbal_yaw_joint</joint_name>
			<p_gain>0.5</p_gain>
			<i_gain>0.01</i_gain>
			<d_gain>0.1</d_gain>
			<i_max>1</i_max>
			<i_min>-1</i_min>
			<cmd_max>30</cmd_max>
			<cmd_min>-30</cmd_min>
		</plugin>
		<plugin filename="ignition-gazebo-joint-position-controller-system" name="ignition::gazebo::systems::JointPositionController">
			<joint_name>gimbal_pitch_joint</joint_name>
			<p_gain>0.8</p_gain>
			<i_gain>0.05</i_gain>
			<d_gain>0.2</d_gain>
			<i_max>10</i_max>
			<i_min>-10</i_min>
			<cmd_max>50</cmd_max>
			<cmd_min>-50</cmd_min>
		</plugin>
	</model>
</sdf>

